<?xml version="1.0" ?>

<robot name="robot_1">
  <!-- <xacro:property name="base_mesh_file" value="file://$(find robot_description)/meshes/base.dae" /> -->
  <!-- <xacro:property name="wheel_mesh_file" value="file://$(find robot_description)/meshes/tire.dae" /> -->
  <gazebo>
    <plugin filename="gz-sim-sensors-system" name="gz::sim::systems::Sensors">
      <render_engine>ogre2</render_engine>
    </plugin>
  </gazebo>
  <link name="base_footprint"/>
  <link name="base_link">
    <visual>
      <origin rpy="0 0 0" xyz="0 0 0"/>
      <geometry>
        <box size="0.35 0.275 0.15"/>
      </geometry>
      <material name="yellow">
        <color rgba="0.8784 0.6627 0.6627 1.0"/>
      </material>
    </visual>
    <collision>
      <origin rpy="0 0 0" xyz="0 0 0"/>
      <geometry>
        <box size="0.35 0.275 0.15"/>
      </geometry>
    </collision>
    <inertial>
      <origin rpy="0 0 0" xyz="0 0 0"/>
      <mass value="1"/>
      <inertia ixx="0.008177083333333335" ixy="0.0" ixz="0.0" iyy="0.012083333333333331" iyz="0.0" izz="0.016510416666666666"/>
    </inertial>
  </link>
  <gazebo reference="base_link">
    <visual>
      <material>
        <ambient>0.8392 0.6314 0.0 1.0</ambient>
        <diffuse>0.8392 0.6314 0.0 1.0</diffuse>
        <specular>0.99 0.99 0.99 1.0</specular>
        <emissive>0.0 0.0 0.0 0.0</emissive>
      </material>
    </visual>
  </gazebo>
  <joint name="base_to_footprint" type="fixed">
    <parent link="base_footprint"/>
    <child link="base_link"/>
    <origin rpy="0 0 0" xyz="0 0 0.14500000000000002"/>
  </joint>
  <link name="left_wheel_link">
    <visual>
      <origin rpy="1.5707963267948966 0 0" xyz="0 0 0"/>
      <geometry>
        <cylinder length="0.05" radius="0.045"/>
      </geometry>
      <material name="blue">
        <color rgba="0.1764 0.4588 0.8509 1.0"/>
      </material>
    </visual>
    <collision>
      <origin rpy="1.5707963267948966 0 0" xyz="0 0 0"/>
      <geometry>
        <cylinder length="0.05" radius="0.045"/>
      </geometry>
    </collision>
    <inertial>
      <origin rpy="0 0 0" xyz="0 0 0"/>
      <mass value="0.1"/>
      <inertia ixx="8.100000000000002e-05" ixy="0" ixz="0" iyy="8.100000000000002e-05" iyz="0" izz="8.100000000000002e-05"/>
    </inertial>
  </link>
  <gazebo reference="left_wheel_link">
    <visual>
      <material>
        <ambient>0.1764 0.4588 0.8509 1.0</ambient>
        <diffuse>0.1764 0.4588 0.8509 1.0</diffuse>
        <specular>0.1764 0.4588 0.8509 1.0</specular>
        <emissive>0.0 0.0 0.0 0.0</emissive>
      </material>
    </visual>
  </gazebo>
  <joint name="left_wheel_joint" type="continuous">
    <axis xyz="0 1 0"/>
    <parent link="base_link"/>
    <child link="left_wheel_link"/>
    <origin rpy="0 0 0" xyz="-0.1 0.14 -0.1"/>
  </joint>
  <link name="right_wheel_link">
    <visual>
      <origin rpy="1.5707963267948966 0 0" xyz="0 0 0"/>
      <geometry>
        <cylinder length="0.05" radius="0.045"/>
      </geometry>
      <material name="blue">
        <color rgba="0.1764 0.4588 0.8509 1.0"/>
      </material>
    </visual>
    <collision>
      <origin rpy="1.5707963267948966 0 0" xyz="0 0 0"/>
      <geometry>
        <cylinder length="0.05" radius="0.045"/>
      </geometry>
    </collision>
    <inertial>
      <origin rpy="0 0 0" xyz="0 0 0"/>
      <mass value="0.1"/>
      <inertia ixx="8.100000000000002e-05" ixy="0" ixz="0" iyy="8.100000000000002e-05" iyz="0" izz="8.100000000000002e-05"/>
    </inertial>
  </link>
  <gazebo reference="right_wheel_link">
    <visual>
      <material>
        <ambient>0.1764 0.4588 0.8509 1.0</ambient>
        <diffuse>0.1764 0.4588 0.8509 1.0</diffuse>
        <specular>0.1764 0.4588 0.8509 1.0</specular>
        <emissive>0.0 0.0 0.0 0.0</emissive>
      </material>
    </visual>
  </gazebo>
  <joint name="right_wheel_joint" type="continuous">
    <axis xyz="0 1 0"/>
    <parent link="base_link"/>
    <child link="right_wheel_link"/>
    <origin rpy="0 0 0" xyz="-0.1 -0.14 -0.1"/>
  </joint>
  <link name="front_caster_wheel_link">
    <visual>
      <origin rpy="0 0 0" xyz="0 0 0"/>
      <geometry>
        <sphere radius="0.07250000000000001"/>
      </geometry>
      <material name="black">
        <color rgba="0.0 0.0 0.0 1.0"/>
      </material>
    </visual>
    <collision>
      <origin rpy="0 0 0" xyz="0 0 0"/>
      <geometry>
        <sphere radius="0.07250000000000001"/>
      </geometry>
    </collision>
    <inertial>
      <origin rpy="0 0 0" xyz="0 0 0"/>
      <mass value="0.01"/>
      <inertia ixx="2.1025000000000006e-05" ixy="0" ixz="0" iyy="2.1025000000000006e-05" iyz="0" izz="2.1025000000000006e-05"/>
    </inertial>
  </link>
  <gazebo reference="front_caster_wheel_link">
    <mu1>0.01</mu1>
    <mu2>0.01</mu2>
  </gazebo>
  <joint name="front_caster_wheel_joint" type="fixed">
    <parent link="base_link"/>
    <child link="front_caster_wheel_link"/>
    <origin rpy="0 0 0" xyz="0.10249999999999998 0 -0.07250000000000001"/>
  </joint>

  <link name="imu_link"/>
  <joint name="imu_to_base_link" type="fixed">
    <parent link="base_link"/>
    <child link="imu_link"/>
    <origin rpy="0 0 0" xyz="0 0 0"/>
  </joint>
  <gazebo>
    <plugin filename="gz-sim-imu-system" name="gz::sim::systems::Imu">
      </plugin>
  </gazebo>
  <gazebo reference="imu_link">
    <sensor name="imu_sensor" type="imu">
      <topic>imu/data</topic>
      <gz_frame_id>imu_link</gz_frame_id>
      <update_rate>5</update_rate>
      <always_on>true</always_on>
      <visualize>true</visualize>
    </sensor>
  </gazebo>
  <link name="laser">
    <visual>
      <origin rpy="0 0 0" xyz="0 0 -0.025"/>
      <geometry>
        <cylinder length="0.05" radius="0.0375"/>
      </geometry>
      <material name="green">
        <color rgba="0.003 0.639 0.223 1.0"/>
      </material>
    </visual>
    <collision>
      <origin rpy="0 0 0" xyz="0 0 -0.025"/>
      <geometry>
        <cylinder length="0.05" radius="0.0375"/>
      </geometry>
    </collision>
    <inertial>
      <origin rpy="0 0 0" xyz="0 0 0"/>
      <mass value="0.1"/>
      <inertia ixx="5.625000000000001e-05" ixy="0" ixz="0" iyy="5.625000000000001e-05" iyz="0" izz="5.625000000000001e-05"/>
    </inertial>
  </link>
  <gazebo reference="laser">
    <visual>
      <material>
        <ambient>0.003 0.639 0.223 1.0</ambient>
        <diffuse>0.003 0.639 0.223 1.0</diffuse>
        <specular>0.003 0.639 0.223 1.0</specular>
        <emissive>0.0 0.0 0.0 0.0</emissive>
      </material>
    </visual>
  </gazebo>
  <joint name="laser_to_base_link" type="fixed">
    <parent link="base_link"/>
    <child link="laser"/>
    <origin rpy="0 0 0" xyz="0.0 0 0.12"/>
  </joint>
  <gazebo reference="laser">
    <sensor name="gpu_lidar" type="gpu_lidar">
      <topic>scan</topic>
      <gz_frame_id>laser</gz_frame_id>
      <update_rate>50</update_rate>
      <always_on>true</always_on>
      <visualize>true</visualize>
      <lidar>
        <scan>
          <horizontal>
            <samples>360</samples>
            <resolution>1</resolution>
            <min_angle>-3.1416</min_angle>
            <max_angle>3.1416</max_angle>
          </horizontal>
          <vertical>
            <samples>1</samples>
            <resolution>1</resolution>
            <min_angle>0.0</min_angle>
            <max_angle>0.0</max_angle>
          </vertical>
        </scan>
        <range>
          <min>0.08</min>
          <max>12.0</max>
          <resolution>0.01</resolution>
        </range>
      </lidar>
    </sensor>
  </gazebo>
  <link name="camera_link">
    <visual>
      <origin rpy="0 0 0" xyz="0 0 0"/>
      <geometry>
        <box size="0.030 0.124 0.030"/>
        <!-- <mesh filename="" scale="0.001 0.001 0.001"/> -->
      </geometry>
      <material name="red">
        <color rgba="0.416 0.051 0.047 1.0"/>
      </material>
    </visual>
    <collision>
      <origin rpy="0 0 0" xyz="0 0 0"/>
      <geometry>
        <box size="0.030 0.124 0.030"/>
      </geometry>
    </collision>
    <inertial>
      <origin rpy="0 0 0" xyz="0 0 0"/>
      <mass value="0.135"/>
      <inertia ixx="0.00018310499999999998" ixy="0.0" ixz="0.0" iyy="2.0249999999999998e-05" iyz="0.0" izz="0.00018310499999999998"/>
    </inertial>
  </link>
  <gazebo reference="camera_link">
    <visual>
      <material>
        <ambient>0.416 0.051 0.047 1.0</ambient>
        <diffuse>0.416 0.051 0.047 1.0</diffuse>
        <specular>0.416 0.051 0.047 1.0</specular>
        <emissive>0.416 0.051 0.047 1.0</emissive>
      </material>
    </visual>
  </gazebo>

    
  <joint name="camera_to_base_link" type="fixed">
    <parent link="base_link"/>
    <child link="camera_link"/>
    <origin rpy="0 0 0" xyz="0.175 0.0 0.045"/>
  </joint>
  <link name="camera_depth_link"/>
  <joint name="camera_depth_joint" type="fixed">
    <origin rpy="0 0 0" xyz="0 0 0"/>
    <parent link="camera_link"/>
    <child link="camera_depth_link"/>
  </joint>
  <gazebo reference="camera_link">
    <sensor name="camera" type="rgbd_camera">
      <topic>camera</topic>
      <gz_frame_id>camera_link</gz_frame_id>
      <update_rate>30.0</update_rate>
      <always_on>true</always_on>
      <visualize>true</visualize>
      <camera>
        <optical_frame_id>camera_depth_link</optical_frame_id>
        <horizontal_fov>1.50098</horizontal_fov>
        <image>
          <width>640</width>
          <height>480</height>
          <format>R8G8B8</format>
        </image>
        <clip>
          <near>0.3</near>
          <far>100</far>
        </clip>
      </camera>
    </sensor>
  </gazebo>
  <gazebo>
    <plugin filename="gz-sim-diff-drive-system" name="gz::sim::systems::DiffDrive">
      <topic>cmd_vel</topic>
      <frame_id>odom</frame_id>
      <child_frame_id>base_footprint</child_frame_id>
      <odom_topic>odom/unfiltered</odom_topic>
      <!-- <tf_topic>/tf</tf_topic> -->
      <left_joint>left_wheel_joint</left_joint>
      <right_joint>right_wheel_joint</right_joint>
      <wheel_separation>0.28</wheel_separation>
      <wheel_radius>0.045</wheel_radius>
      <odom_publish_frequency>50</odom_publish_frequency>
      <tf_topic>/tf</tf_topic>
    </plugin>
  </gazebo>
  <gazebo>
    <plugin filename="gz-sim-joint-state-publisher-system" name="gz::sim::systems::JointStatePublisher">
      <topic>joint_states</topic>
      <update_rate>30</update_rate>
      <joint_name>left_wheel_joint</joint_name>
      <joint_name>right_wheel_joint</joint_name>
    </plugin>
  </gazebo>
</robot>